Workbook

Sheet Xarajatlar
A1: Yuksalish Agro: 2026-yil noyabr – 2027-yil dekabr xarajatlari (mln so'm)
A2: Qanday to'ldiriladi: sariq kataklardagi ko'k raqamlarni (oylar bo'yicha summa, miqdor, narx, manba) o'zgartiring. Qora raqamlar formulalar, ularni o'zgartirmang.
A3: Jami ustuni oylar yig'indisi. Tekshiruv ustuni: miqdor × narx bilan oylar yig'indisi orasidagi farq (0 bo'lishi kerak). Manba: "Kredit" yoki "O'z mablag'i".
A5: № | B5: Bo'lim | C5: Xarajat moddasi | D5: Birlik | E5: Miqdor | F5: Narx, mln so'm | G5: Manba | H5: Jami, mln so'm | I5: Tekshiruv | J5: Noy 2026 | K5: Dek 2026 | L5: Yan 2027 | M5: Fev 2027 | N5: Mar 2027 | O5: Apr 2027 | P5: May 2027 | Q5: Iyn 2027 | R5: Iyl 2027 | S5: Avg 2027 | T5: Sen 2027 | U5: Okt 2027 | V5: Noy 2027 | W5: Dek 2027 | X5: Izoh
B6: Kapital xarajatlar | C6: Kapital xarajatlar: qurilish, texnika, mol, texnologiyalar
A7: 1 | B7: Kapital | C7: Loyiha-smeta hujjatlari va ruxsatnomalar | D7: kompl. | E7: 1 | F7: 60 | G7: O'z mablag'i | H7: =SUM(J7:W7) -> 60 | I7: =ROUND(E7*F7-H7,1) -> 0 | J7: 60 | K7: 0 | L7: 0 | M7: 0 | N7: 0 | O7: 0 | P7: 0 | Q7: 0 | R7: 0 | S7: 0 | T7: 0 | U7: 0 | V7: 0 | W7: 0
A8: 2 | B8: Kapital | C8: Molxona, bog'lanmasdan saqlash, 120 joy | D8: m² | E8: 1400 | F8: 0.4286 | G8: O'z mablag'i | H8: =SUM(J8:W8) -> 600 | I8: =ROUND(E8*F8-H8,1) -> 0 | J8: 90 | K8: 90 | L8: 150 | M8: 150 | N8: 120 | O8: 0 | P8: 0 | Q8: 0 | R8: 0 | S8: 0 | T8: 0 | U8: 0 | V8: 0 | W8: 0 | X8: Qurilish: noyabr–dekabr 30% avans, yanvar–mart 70%
A9: 3 | B9: Kapital | C9: Buzoqxona va g'unajinlar binosi | D9: m² | E9: 700 | F9: 0.3571 | G9: O'z mablag'i | H9: =SUM(J9:W9) -> 250 | I9: =ROUND(E9*F9-H9,1) -> 0 | J9: 37.5 | K9: 37.5 | L9: 62.5 | M9: 62.5 | N9: 50 | O9: 0 | P9: 0 | Q9: 0 | R9: 0 | S9: 0 | T9: 0 | U9: 0 | V9: 0 | W9: 0
A10: 4 | B10: Kapital | C10: Bo'rdoqi buqalar uchun ayvon | D10: m² | E10: 600 | F10: 0.2 | G10: O'z mablag'i | H10: =SUM(J10:W10) -> 120 | I10: =ROUND(E10*F10-H10,1) -> 0 | J10: 18 | K10: 18 | L10: 30 | M10: 30 | N10: 24 | O10: 0 | P10: 0 | Q10: 0 | R10: 0 | S10: 0 | T10: 0 | U10: 0 | V10: 0 | W10: 0
A11: 5 | B11: Kapital | C11: Yopiq yem-xashak ombori (angar) | D11: m² | E11: 800 | F11: 0.1 | G11: O'z mablag'i | H11: =SUM(J11:W11) -> 80 | I11: =ROUND(E11*F11-H11,1) -> 0 | J11: 12 | K11: 12 | L11: 20 | M11: 20 | N11: 16 | O11: 0 | P11: 0 | Q11: 0 | R11: 0 | S11: 0 | T11: 0 | U11: 0 | V11: 0 | W11: 0
A12: 6 | B12: Kapital | C12: Silos transheyalari (beton) | D12: m³ | E12: 1300 | F12: 0.0923 | G12: O'z mablag'i | H12: =SUM(J12:W12) -> 120 | I12: =ROUND(E12*F12-H12,1) -> 0 | J12: 18 | K12: 18 | L12: 30 | M12: 30 | N12: 24 | O12: 0 | P12: 0 | Q12: 0 | R12: 0 | S12: 0 | T12: 0 | U12: 0 | V12: 0 | W12: 0
A13: 7 | B13: Kapital | C13: Quduq, suv tarmog'i, avtosug'orgichlar | D13: kompl. | E13: 1 | F13: 50 | G13: O'z mablag'i | H13: =SUM(J13:W13) -> 50 | I13: =ROUND(E13*F13-H13,1) -> 0 | J13: 7.5 | K13: 7.5 | L13: 12.5 | M13: 12.5 | N13: 10 | O13: 0 | P13: 0 | Q13: 0 | R13: 0 | S13: 0 | T13: 0 | U13: 0 | V13: 0 | W13: 0
A14: 8 | B14: Kapital | C14: Transformator, elektr tarmog'i, ventilyator va sovutish | D14: kompl. | E14: 1 | F14: 100 | G14: O'z mablag'i | H14: =SUM(J14:W14) -> 100 | I14: =ROUND(E14*F14-H14,1) -> 0 | J14: 15 | K14: 15 | L14: 25 | M14: 25 | N14: 20 | O14: 0 | P14: 0 | Q14: 0 | R14: 0 | S14: 0 | T14: 0 | U14: 0 | V14: 0 | W14: 0
A15: 9 | B15: Kapital | C15: Veterinariya punkti, dezbarer, ofis va maishiy xona | D15: kompl. | E15: 1 | F15: 30 | G15: O'z mablag'i | H15: =SUM(J15:W15) -> 30 | I15: =ROUND(E15*F15-H15,1) -> 0 | J15: 4.5 | K15: 4.5 | L15: 7.5 | M15: 7.5 | N15: 6 | O15: 0 | P15: 0 | Q15: 0 | R15: 0 | S15: 0 | T15: 0 | U15: 0 | V15: 0 | W15: 0
A16: 10 | B16: Kapital | C16: Go'ng maydoni, ichki yo'l, devor | D16: kompl. | E16: 1 | F16: 10 | G16: O'z mablag'i | H16: =SUM(J16:W16) -> 10 | I16: =ROUND(E16*F16-H16,1) -> 0 | J16: 1.5 | K16: 1.5 | L16: 2.5 | M16: 2.5 | N16: 2 | O16: 0 | P16: 0 | Q16: 0 | R16: 0 | S16: 0 | T16: 0 | U16: 0 | V16: 0 | W16: 0
A17: 11 | B17: Kapital | C17: Silosni germetik yopish tizimi (himoya to'ri, qum qopchalari) | D17: kompl. | E17: 1 | F17: 10 | G17: O'z mablag'i | H17: =SUM(J17:W17) -> 10 | I17: =ROUND(E17*F17-H17,1) -> 0 | J17: 0 | K17: 0 | L17: 0 | M17: 0 | N17: 0 | O17: 10 | P17: 0 | Q17: 0 | R17: 0 | S17: 0 | T17: 0 | U17: 0 | V17: 0 | W17: 0 | X17: Sotib olingan silosni saqlash uchun
A18: 12 | B18: Kapital | C18: Sog'ish zali (2×6) va 3 tonnalik sut sovutgich | D18: kompl. | E18: 1 | F18: 300 | G18: O'z mablag'i | H18: =SUM(J18:W18) -> 300 | I18: =ROUND(E18*F18-H18,1) -> 0 | J18: 0 | K18: 0 | L18: 0 | M18: 150 | N18: 150 | O18: 0 | P18: 0 | Q18: 0 | R18: 0 | S18: 0 | T18: 0 | U18: 0 | V18: 0 | W18: 0
A19: 13 | B19: Kapital | C19: Traktor (80–100 o.k.) | D19: dona | E19: 1 | F19: 20 | G19: O'z mablag'i | H19: =SUM(J19:W19) -> 20 | I19: =ROUND(E19*F19-H19,1) -> 0 | J19: 20 | K19: 0 | L19: 0 | M19: 0 | N19: 0 | O19: 0 | P19: 0 | Q19: 0 | R19: 0 | S19: 0 | T19: 0 | U19: 0 | V19: 0 | W19: 0 | X19: Kuzgi ekish va qurilish ishlari uchun
A20: 14 | B20: Kapital | C20: Tirkama va frontal yuklagich | D20: kompl. | E20: 1 | F20: 5 | G20: O'z mablag'i | H20: =SUM(J20:W20) -> 5 | I20: =ROUND(E20*F20-H20,1) -> 0 | J20: 5 | K20: 0 | L20: 0 | M20: 0 | N20: 0 | O20: 0 | P20: 0 | Q20: 0 | R20: 0 | S20: 0 | T20: 0 | U20: 0 | V20: 0 | W20: 0
A21: 15 | B21: Kapital | C21: Ozuqa aralashtirgich-tarqatgich (miksyer) | D21: dona | E21: 1 | F21: 50 | G21: O'z mablag'i | H21: =SUM(J21:W21) -> 50 | I21: =ROUND(E21*F21-H21,1) -> 0 | J21: 0 | K21: 0 | L21: 0 | M21: 0 | N21: 50 | O21: 0 | P21: 0 | Q21: 0 | R21: 0 | S21: 0 | T21: 0 | U21: 0 | V21: 0 | W21: 0
A22: 16 | B22: Kapital | C22: Beda uchun o'roq, panshaxa va press | D22: kompl. | E22: 1 | F22: 120 | G22: O'z mablag'i | H22: =SUM(J22:W22) -> 120 | I22: =ROUND(E22*F22-H22,1) -> 0 | J22: 0 | K22: 0 | L22: 0 | M22: 0 | N22: 0 | O22: 0 | P22: 0 | Q22: 0 | R22: 120 | S22: 0 | T22: 0 | U22: 0 | V22: 0 | W22: 0 | X22: Birinchi beda o'rimi avgustda
A23: 17 | B23: Kapital | C23: Texnologiya: Podani raqamli kuzatish (bo'yinbog', pedometr, shlyuz) | D23: kompl. | E23: 1 | F23: 60 | G23: O'z mablag'i | H23: =SUM(J23:W23) -> 60 | I23: =ROUND(E23*F23-H23,1) -> 0 | J23: 0 | K23: 0 | L23: 0 | M23: 0 | N23: 0 | O23: 60 | P23: 0 | Q23: 0 | R23: 0 | S23: 0 | T23: 0 | U23: 0 | V23: 0 | W23: 0
A24: 18 | B24: Kapital | C24: Texnologiya: Sut hisoblagichlari va podani boshqarish dasturi | D24: kompl. | E24: 1 | F24: 60 | G24: O'z mablag'i | H24: =SUM(J24:W24) -> 60 | I24: =ROUND(E24*F24-H24,1) -> 0 | J24: 0 | K24: 0 | L24: 0 | M24: 0 | N24: 60 | O24: 0 | P24: 0 | Q24: 0 | R24: 0 | S24: 0 | T24: 0 | U24: 0 | V24: 0 | W24: 0
A25: 19 | B25: Kapital | C25: Texnologiya: Ozuqani aniq taqsimlash tizimi | D25: kompl. | E25: 1 | F25: 20 | G25: O'z mablag'i | H25: =SUM(J25:W25) -> 20 | I25: =ROUND(E25*F25-H25,1) -> 0 | J25: 0 | K25: 0 | L25: 0 | M25: 0 | N25: 20 | O25: 0 | P25: 0 | Q25: 0 | R25: 0 | S25: 0 | T25: 0 | U25: 0 | V25: 0 | W25: 0
A26: 20 | B26: Kapital | C26: Texnologiya: Mikroiqlimni avtomatik boshqarish | D26: kompl. | E26: 1 | F26: 40 | G26: O'z mablag'i | H26: =SUM(J26:W26) -> 40 | I26: =ROUND(E26*F26-H26,1) -> 0 | J26: 0 | K26: 0 | L26: 0 | M26: 0 | N26: 40 | O26: 0 | P26: 0 | Q26: 0 | R26: 0 | S26: 0 | T26: 0 | U26: 0 | V26: 0 | W26: 0
A27: 21 | B27: Kapital | C27: Texnologiya: Avtomatik go'ng tozalash | D27: kompl. | E27: 1 | F27: 80 | G27: O'z mablag'i | H27: =SUM(J27:W27) -> 80 | I27: =ROUND(E27*F27-H27,1) -> 0 | J27: 0 | K27: 0 | L27: 0 | M27: 80 | N27: 0 | O27: 0 | P27: 0 | Q27: 0 | R27: 0 | S27: 0 | T27: 0 | U27: 0 | V27: 0 | W27: 0
A28: 22 | B28: Kapital | C28: Texnologiya: Buzoqlarni avtomatik sut bilan boqish apparati | D28: kompl. | E28: 1 | F28: 20 | G28: O'z mablag'i | H28: =SUM(J28:W28) -> 20 | I28: =ROUND(E28*F28-H28,1) -> 0 | J28: 0 | K28: 0 | L28: 0 | M28: 0 | N28: 20 | O28: 0 | P28: 0 | Q28: 0 | R28: 0 | S28: 0 | T28: 0 | U28: 0 | V28: 0 | W28: 0
A29: 23 | B29: Kapital | C29: Naslli bug'oz sigir (Xitoy), yetkazish va karantin bilan | D29: bosh | E29: 100 | F29: 38 | G29: Kredit | H29: =SUM(J29:W29) -> 3800 | I29: =ROUND(E29*F29-H29,1) -> 0 | J29: 0 | K29: 0 | L29: 0 | M29: 0 | N29: 1140 | O29: 2660 | P29: 0 | Q29: 0 | R29: 0 | S29: 0 | T29: 0 | U29: 0 | V29: 0 | W29: 0 | X29: Mart: 30% oldindan to'lov, aprel: qolgan 70% va yetkazib berish
A30: 24 | B30: Kapital | C30: Kutilmagan xarajatlar uchun zaxira | D30: kompl. | E30: 1 | F30: 120 | G30: O'z mablag'i | H30: =SUM(J30:W30) -> 120 | I30: =ROUND(E30*F30-H30,1) -> 0 | J30: 15 | K30: 15 | L30: 20 | M30: 20 | N30: 20 | O30: 10 | P30: 0 | Q30: 0 | R30: 10 | S30: 0 | T30: 0 | U30: 10 | V30: 0 | W30: 0
C31: Jami: kapital xarajatlar | H31: =SUM(H7:H30) -> 6125 | J31: =SUM(J7:J30) -> 304 | K31: =SUM(K7:K30) -> 219 | L31: =SUM(L7:L30) -> 360 | M31: =SUM(M7:M30) -> 590 | N31: =SUM(N7:N30) -> 1772 | O31: =SUM(O7:O30) -> 2740 | P31: =SUM(P7:P30) -> 0 | Q31: =SUM(Q7:Q30) -> 0 | ... W31: =SUM(W7:W30) -> 0
B33: Joriy xarajatlar | C33: Joriy xarajatlar: ekin, ozuqa, ish haqi va boshqalar
A34: 25 | B34: Joriy | C34: Bug'doy 2026/27: yer haydash, urug', ekish, o'g'it (29.0 ga) | D34: ga | E34: 29 | F34: 4.5 | G34: O'z mablag'i | H34: =SUM(J34:W34) -> 130.5 | I34: =ROUND(E34*F34-H34,1) -> 0 | J34: 130.5 | K34: 0 | L34: 0 | M34: 0 | N34: 0 | O34: 0 | P34: 0 | Q34: 0 | R34: 0 | S34: 0 | T34: 0 | U34: 0 | V34: 0 | W34: 0 | X34: 2026-yil noyabr, aylanma mablag'dan
A35: 26 | B35: Joriy | C35: Bug'doy 2026/27: bahorgi o'g'itlash va sug'orish | D35: ga | E35: 29 | F35: 2.43 | G35: O'z mablag'i | H35: =SUM(J35:W35) -> 70.5 | I35: =ROUND(E35*F35-H35,1) -> 0 | J35: 0 | K35: 0 | L35: 0 | M35: 0 | N35: 70.5 | O35: 0 | P35: 0 | Q35: 0 | R35: 0 | S35: 0 | T35: 0 | U35: 0 | V35: 0 | W35: 0
A36: 27 | B36: Joriy | C36: Bug'doy 2026/27: o'rim (kombayn xizmati) | D36: ga | E36: 29 | F36: 2.07 | G36: O'z mablag'i | H36: =SUM(J36:W36) -> 60 | I36: =ROUND(E36*F36-H36,1) -> 0 | J36: 0 | K36: 0 | L36: 0 | M36: 0 | N36: 0 | O36: 0 | P36: 0 | Q36: 60 | R36: 0 | S36: 0 | T36: 0 | U36: 0 | V36: 0 | W36: 0
A37: 28 | B37: Joriy | C37: Beda ekish: urug', yer tayyorlash (5.1 ga) | D37: ga | E37: 5.1 | F37: 12 | G37: O'z mablag'i | H37: =SUM(J37:W37) -> 61.2 | I37: =ROUND(E37*F37-H37,1) -> 0 | J37: 0 | K37: 0 | L37: 0 | M37: 0 | N37: 0 | O37: 0 | P37: 0 | Q37: 0 | R37: 61.2 | S37: 0 | T37: 0 | U37: 0 | V37: 0 | W37: 0
A38: 29 | B38: Joriy | C38: Bug'doy 2027/28: haydash, urug', ekish, o'g'it (23.9 ga) | D38: ga | E38: 23.9 | F38: 4.5 | G38: O'z mablag'i | H38: =SUM(J38:W38) -> 107.5 | I38: =ROUND(E38*F38-H38,1) -> 0 | J38: 0 | K38: 0 | L38: 0 | M38: 0 | N38: 0 | O38: 0 | P38: 0 | Q38: 0 | R38: 0 | S38: 0 | T38: 0 | U38: 0 | V38: 107.5 | W38: 0 | X38: Modelda 2028-yil xarajatiga yozilgan, bu yerda pul chiqqan oyda
A39: 30 | B39: Joriy | C39: Konsentrat yem (omuxta yem, kunjara), sotib olinadi | D39: kg | G39: O'z mablag'i | H39: =SUM(J39:W39) -> 301.4 | J39: 0 | K39: 0 | L39: 0 | M39: 0 | N39: 0 | O39: 52.9 | P39: 52.9 | Q39: 0 | R39: 0 | S39: 0 | T39: 0 | U39: 49.6 | V39: 73 | W39: 73 | X39: 3700 so'm/kg; iyun–sentabrda o'z bug'doyimiz ishlatiladi
A40: 31 | B40: Joriy | C40: Silos sotib olish | D40: kg | G40: O'z mablag'i | H40: =SUM(J40:W40) -> 599.7 | J40: 0 | K40: 0 | L40: 0 | M40: 0 | N40: 0 | O40: 52.1 | P40: 52.1 | Q40: 52.1 | R40: 73.9 | S40: 73.9 | T40: 73.9 | U40: 73.9 | V40: 73.9 | W40: 73.9 | X40: Jami summa egasi tomonidan kiritilgan (600 mln so'm); o'z silosi 2028-yildan
A41: 32 | B41: Joriy | C41: Beda pichani sotib olish | D41: kg | G41: O'z mablag'i | H41: =SUM(J41:W41) -> 50.2 | J41: 0 | K41: 0 | L41: 0 | M41: 0 | N41: 0 | O41: 5 | P41: 5 | Q41: 5 | R41: 7 | S41: 3.6 | T41: 3.6 | U41: 7 | V41: 7 | W41: 7 | X41: 2000 so'm/kg
A42: 33 | B42: Joriy | C42: Somon sotib olish | D42: kg | G42: O'z mablag'i | H42: =SUM(J42:W42) -> 0 | J42: 0 | K42: 0 | L42: 0 | M42: 0 | N42: 0 | O42: 0 | P42: 0 | Q42: 0 | R42: 0 | S42: 0 | T42: 0 | U42: 0 | V42: 0 | W42: 0 | X42: Iyundan o'z somonimiz
...

Sheet Jamlanma
A1: Jamlanma: oylar bo'yicha xarajatlar va moliyalashtirish manbasi (mln so'm)
A2: Bu varaq formulalar bilan "Xarajatlar" varag'idan hisoblanadi, uni tahrirlash shart emas.
A4: Ko'rsatkich | B4: Jami | C4: Noy 2026 | D4: Dek 2026 | E4: Yan 2027 | F4: Fev 2027 | G4: Mar 2027 | H4: Apr 2027 | I4: May 2027 | J4: Iyn 2027 | K4: Iyl 2027 | L4: Avg 2027 | M4: Sen 2027 | N4: Okt 2027 | O4: Noy 2027 | P4: Dek 2027
A5: Kapital xarajatlar, kredit hisobidan | B5: =SUM(C5:P5) -> 3800 | C5: =SUMIFS(Xarajatlar!J7:J64,Xarajatlar!$B$7:$B$64,"Kapital",Xarajatlar!$G$7:$G$64,"Kredit") -> 0 | D5: =SUMIFS(Xarajatlar!K7:K64,Xarajatlar!$B$7:$B$64,"Kapital",Xarajatlar!$G$7:$G$64,"Kredit") -> 0 | E5: =SUMIFS(Xarajatlar!L7:L64,Xarajatlar!$B$7:$B$64,"Kapital",Xarajatlar!$G$7:$G$64,"Kredit") -> 0 | F5: =SUMIFS(Xarajatlar!M7:M64,Xarajatlar!$B$7:$B$64,"Kapital",Xarajatlar!$G$7:$G$64,"Kredit") -> 0 | G5: =SUMIFS(Xarajatlar!N7:N64,Xarajatlar!$B$7:$B$64,"Kapital",Xarajatlar!$G$7:$G$64,"Kredit") -> 1140 | H5: =SUMIFS(Xarajatlar!O7:O64,Xarajatlar!$B$7:$B$64,"Kapital",Xarajatlar!$G$7:$G$64,"Kredit") -> 2660 | I5: =SUMIFS(Xarajatlar!P7:P64,Xarajatlar!$B$7:$B$64,"Kapital",Xarajatlar!$G$7:$G$64,"Kredit") -> 0 | J5: =SUMIFS(Xarajatlar!Q7:Q64,Xarajatlar!$B$7:$B$64,"Kapital",Xarajatlar!$G$7:$G$64,"Kredit") -> 0 | ... P5: =SUMIFS(Xarajatlar!W7:W64,Xarajatlar!$B$7:$B$64,"Kapital",Xarajatlar!$G$7:$G$64,"Kredit") -> 0
A6: Kapital xarajatlar, o'z mablag'i hisobidan | B6: =SUM(C6:P6) -> 2325 | C6: =SUMIFS(Xarajatlar!J7:J64,Xarajatlar!$B$7:$B$64,"Kapital",Xarajatlar!$G$7:$G$64,"O'z mablag'i") -> 304 | D6: =SUMIFS(Xarajatlar!K7:K64,Xarajatlar!$B$7:$B$64,"Kapital",Xarajatlar!$G$7:$G$64,"O'z mablag'i") -> 219 | E6: =SUMIFS(Xarajatlar!L7:L64,Xarajatlar!$B$7:$B$64,"Kapital",Xarajatlar!$G$7:$G$64,"O'z mablag'i") -> 360 | F6: =SUMIFS(Xarajatlar!M7:M64,Xarajatlar!$B$7:$B$64,"Kapital",Xarajatlar!$G$7:$G$64,"O'z mablag'i") -> 590 | G6: =SUMIFS(Xarajatlar!N7:N64,Xarajatlar!$B$7:$B$64,"Kapital",Xarajatlar!$G$7:$G$64,"O'z mablag'i") -> 632 | H6: =SUMIFS(Xarajatlar!O7:O64,Xarajatlar!$B$7:$B$64,"Kapital",Xarajatlar!$G$7:$G$64,"O'z mablag'i") -> 80 | I6: =SUMIFS(Xarajatlar!P7:P64,Xarajatlar!$B$7:$B$64,"Kapital",Xarajatlar!$G$7:$G$64,"O'z mablag'i") -> 0 | J6: =SUMIFS(Xarajatlar!Q7:Q64,Xarajatlar!$B$7:$B$64,"Kapital",Xarajatlar!$G$7:$G$64,"O'z mablag'i") -> 0 | ... P6: =SUMIFS(Xarajatlar!W7:W64,Xarajatlar!$B$7:$B$64,"Kapital",Xarajatlar!$G$7:$G$64,"O'z mablag'i") -> 0
A7: Joriy xarajatlar, o'z mablag'i hisobidan | B7: =SUM(C7:P7) -> 2891.9 | C7: =SUMIFS(Xarajatlar!J7:J64,Xarajatlar!$B$7:$B$64,"Joriy",Xarajatlar!$G$7:$G$64,"O'z mablag'i") -> 192.3 | D7: =SUMIFS(Xarajatlar!K7:K64,Xarajatlar!$B$7:$B$64,"Joriy",Xarajatlar!$G$7:$G$64,"O'z mablag'i") -> 61.8 | E7: =SUMIFS(Xarajatlar!L7:L64,Xarajatlar!$B$7:$B$64,"Joriy",Xarajatlar!$G$7:$G$64,"O'z mablag'i") -> 57.3 | F7: =SUMIFS(Xarajatlar!M7:M64,Xarajatlar!$B$7:$B$64,"Joriy",Xarajatlar!$G$7:$G$64,"O'z mablag'i") -> 57.3 | G7: =SUMIFS(Xarajatlar!N7:N64,Xarajatlar!$B$7:$B$64,"Joriy",Xarajatlar!$G$7:$G$64,"O'z mablag'i") -> 158.1 | H7: =SUMIFS(Xarajatlar!O7:O64,Xarajatlar!$B$7:$B$64,"Joriy",Xarajatlar!$G$7:$G$64,"O'z mablag'i") -> 222.6 | I7: =SUMIFS(Xarajatlar!P7:P64,Xarajatlar!$B$7:$B$64,"Joriy",Xarajatlar!$G$7:$G$64,"O'z mablag'i") -> 222.6 | J7: =SUMIFS(Xarajatlar!Q7:Q64,Xarajatlar!$B$7:$B$64,"Joriy",Xarajatlar!$G$7:$G$64,"O'z mablag'i") -> 256.6 | ... P7: =SUMIFS(Xarajatlar!W7:W64,Xarajatlar!$B$7:$B$64,"Joriy",Xarajatlar!$G$7:$G$64,"O'z mablag'i") -> 291.7
A8: Joriy xarajatlar, kredit hisobidan | B8: =SUM(C8:P8) -> 0 | C8: =SUMIFS(Xarajatlar!J7:J64,Xarajatlar!$B$7:$B$64,"Joriy",Xarajatlar!$G$7:$G$64,"Kredit") -> 0 | D8: =SUMIFS(Xarajatlar!K7:K64,Xarajatlar!$B$7:$B$64,"Joriy",Xarajatlar!$G$7:$G$64,"Kredit") -> 0 | E8: =SUMIFS(Xarajatlar!L7:L64,Xarajatlar!$B$7:$B$64,"Joriy",Xarajatlar!$G$7:$G$64,"Kredit") -> 0 | F8: =SUMIFS(Xarajatlar!M7:M64,Xarajatlar!$B$7:$B$64,"Joriy",Xarajatlar!$G$7:$G$64,"Kredit") -> 0 | G8: =SUMIFS(Xarajatlar!N7:N64,Xarajatlar!$B$7:$B$64,"Joriy",Xarajatlar!$G$7:$G$64,"Kredit") -> 0 | H8: =SUMIFS(Xarajatlar!O7:O64,Xarajatlar!$B$7:$B$64,"Joriy",Xarajatlar!$G$7:$G$64,"Kredit") -> 0 | I8: =SUMIFS(Xarajatlar!P7:P64,Xarajatlar!$B$7:$B$64,"Joriy",Xarajatlar!$G$7:$G$64,"Kredit") -> 0 | J8: =SUMIFS(Xarajatlar!Q7:Q64,Xarajatlar!$B$7:$B$64,"Joriy",Xarajatlar!$G$7:$G$64,"Kredit") -> 0 | ... P8: =SUMIFS(Xarajatlar!W7:W64,Xarajatlar!$B$7:$B$64,"Joriy",Xarajatlar!$G$7:$G$64,"Kredit") -> 0
A9: Kredit hisobidan jami | B9: =SUM(C9:P9) -> 3800 | C9: =C5+C8 -> 0 | D9: =D5+D8 -> 0 | E9: =E5+E8 -> 0 | F9: =F5+F8 -> 0 | G9: =G5+G8 -> 1140 | H9: =H5+H8 -> 2660 | I9: =I5+I8 -> 0 | J9: =J5+J8 -> 0 | ... P9: =P5+P8 -> 0
A10: O'z mablag'i hisobidan jami | B10: =SUM(C10:P10) -> 5216.9 | C10: =C6+C7 -> 496.3 | D10: =D6+D7 -> 280.8 | E10: =E6+E7 -> 417.3 | F10: =F6+F7 -> 647.3 | G10: =G6+G7 -> 790.1 | H10: =H6+H7 -> 302.6 | I10: =I6+I7 -> 222.6 | J10: =J6+J7 -> 256.6 | ... P10: =P6+P7 -> 291.7
A11: Jami xarajatlar | B11: =SUM(C11:P11) -> 9016.9 | C11: =C9+C10 -> 496.3 | D11: =D9+D10 -> 280.8 | E11: =E9+E10 -> 417.3 | F11: =F9+F10 -> 647.3 | G11: =G9+G10 -> 1930.1 | H11: =H9+H10 -> 2962.6 | I11: =I9+I10 -> 222.6 | J11: =J9+J10 -> 256.6 | ... P11: =P9+P10 -> 291.7
A12: O'z mablag'i, yig'ma (boshidan) | C12: =C10 -> 496.3 | D12: =C12+D10 -> 777.1 | E12: =D12+E10 -> 1194.4 | F12: =E12+F10 -> 1841.7 | G12: =F12+G10 -> 2631.8 | H12: =G12+H10 -> 2934.4 | I12: =H12+I10 -> 3157 | J12: =I12+J10 -> 3413.6 | K12: =J12+K10 -> 3832.8 | ... P12: =O12+P10 -> 5216.9
A14: Eslatma: 2027-yilda fermaga sut, buqa va bug'doy sotuvidan tushum ham keladi (biznes-rejadagi 9-bo'lim). Bu jadval faqat xarajatlarni ko'rsatadi, shuning uchun o'z mablag'idan haqiqatda kerak bo'ladigan pul bundan kamroq.
